[2024-01-05T13:22:01.662+0000] {logging_mixin.py:188} INFO - Changing /opt/***/logs/dag_id=User_counter/run_id=scheduled__2024-01-05T13:21:00+00:00/task_id=PostgresTable permission to 509
[2024-01-05T13:22:01.670+0000] {logging_mixin.py:188} INFO - Failed to change /opt/***/logs/dag_id=User_counter/run_id=scheduled__2024-01-05T13:21:00+00:00/task_id=PostgresTable permission to 509: [Errno 1] Operation not permitted: '/opt/***/logs/dag_id=User_counter/run_id=scheduled__2024-01-05T13:21:00+00:00/task_id=PostgresTable'
[2024-01-05T13:22:01.725+0000] {logging_mixin.py:188} INFO - Changing /opt/***/logs/dag_id=User_counter/run_id=scheduled__2024-01-05T13:21:00+00:00/task_id=PostgresTable permission to 509
[2024-01-05T13:22:01.726+0000] {logging_mixin.py:188} INFO - Failed to change /opt/***/logs/dag_id=User_counter/run_id=scheduled__2024-01-05T13:21:00+00:00/task_id=PostgresTable permission to 509: [Errno 1] Operation not permitted: '/opt/***/logs/dag_id=User_counter/run_id=scheduled__2024-01-05T13:21:00+00:00/task_id=PostgresTable'
[2024-01-05T13:22:01.790+0000] {taskinstance.py:1957} INFO - Dependencies all met for dep_context=non-requeueable deps ti=<TaskInstance: User_counter.PostgresTable scheduled__2024-01-05T13:21:00+00:00 [queued]>
[2024-01-05T13:22:01.804+0000] {taskinstance.py:1957} INFO - Dependencies all met for dep_context=requeueable deps ti=<TaskInstance: User_counter.PostgresTable scheduled__2024-01-05T13:21:00+00:00 [queued]>
[2024-01-05T13:22:01.805+0000] {taskinstance.py:2171} INFO - Starting attempt 1 of 2
[2024-01-05T13:22:01.825+0000] {taskinstance.py:2192} INFO - Executing <Task(PostgresOperator): PostgresTable> on 2024-01-05 13:21:00+00:00
[2024-01-05T13:22:01.831+0000] {standard_task_runner.py:60} INFO - Started process 20389 to run task
[2024-01-05T13:22:01.837+0000] {standard_task_runner.py:87} INFO - Running: ['***', 'tasks', 'run', 'User_counter', 'PostgresTable', 'scheduled__2024-01-05T13:21:00+00:00', '--job-id', '64', '--raw', '--subdir', 'DAGS_FOLDER/User_counter.py', '--cfg-path', '/tmp/tmpr3qgby9n']
[2024-01-05T13:22:01.841+0000] {standard_task_runner.py:88} INFO - Job 64: Subtask PostgresTable
[2024-01-05T13:22:01.905+0000] {logging_mixin.py:188} INFO - Changing /opt/***/logs/dag_id=User_counter/run_id=scheduled__2024-01-05T13:21:00+00:00/task_id=PostgresTable permission to 509
[2024-01-05T13:22:01.906+0000] {logging_mixin.py:188} INFO - Failed to change /opt/***/logs/dag_id=User_counter/run_id=scheduled__2024-01-05T13:21:00+00:00/task_id=PostgresTable permission to 509: [Errno 1] Operation not permitted: '/opt/***/logs/dag_id=User_counter/run_id=scheduled__2024-01-05T13:21:00+00:00/task_id=PostgresTable'
[2024-01-05T13:22:01.908+0000] {task_command.py:423} INFO - Running <TaskInstance: User_counter.PostgresTable scheduled__2024-01-05T13:21:00+00:00 [running]> on host b8b6020a6ce0
[2024-01-05T13:22:02.043+0000] {taskinstance.py:2481} INFO - Exporting env vars: AIRFLOW_CTX_DAG_OWNER='Airflow' AIRFLOW_CTX_DAG_ID='User_counter' AIRFLOW_CTX_TASK_ID='PostgresTable' AIRFLOW_CTX_EXECUTION_DATE='2024-01-05T13:21:00+00:00' AIRFLOW_CTX_TRY_NUMBER='1' AIRFLOW_CTX_DAG_RUN_ID='scheduled__2024-01-05T13:21:00+00:00'
[2024-01-05T13:22:02.048+0000] {sql.py:276} INFO - Executing: 
            CREATE TABLE IF NOT EXISTS pet (
            pet_id SERIAL PRIMARY KEY,
            name VARCHAR NOT NULL,
            pet_type VARCHAR NOT NULL,
            birth_date DATE NOT NULL,
            OWNER VARCHAR NOT NULL);
          
[2024-01-05T13:22:02.059+0000] {base.py:83} INFO - Using connection ID 'Postgres-connection' for task execution.
[2024-01-05T13:22:02.072+0000] {base.py:83} INFO - Using connection ID 'Postgres-connection' for task execution.
[2024-01-05T13:22:02.102+0000] {taskinstance.py:2699} ERROR - Task failed with exception
Traceback (most recent call last):
  File "/home/airflow/.local/lib/python3.8/site-packages/airflow/models/taskinstance.py", line 433, in _execute_task
    result = execute_callable(context=context, **execute_callable_kwargs)
  File "/home/airflow/.local/lib/python3.8/site-packages/airflow/providers/common/sql/operators/sql.py", line 282, in execute
    output = hook.run(
  File "/home/airflow/.local/lib/python3.8/site-packages/airflow/providers/common/sql/hooks/sql.py", line 385, in run
    with closing(self.get_conn()) as conn:
  File "/home/airflow/.local/lib/python3.8/site-packages/airflow/providers/postgres/hooks/postgres.py", line 158, in get_conn
    self.conn = psycopg2.connect(**conn_args)
  File "/home/airflow/.local/lib/python3.8/site-packages/psycopg2/__init__.py", line 122, in connect
    conn = _connect(dsn, connection_factory=connection_factory, **kwasync)
psycopg2.OperationalError: could not translate host name "host.local.internal" to address: Name or service not known

[2024-01-05T13:22:02.113+0000] {taskinstance.py:1138} INFO - Marking task as UP_FOR_RETRY. dag_id=User_counter, task_id=PostgresTable, execution_date=20240105T132100, start_date=20240105T132201, end_date=20240105T132202
[2024-01-05T13:22:02.155+0000] {standard_task_runner.py:107} ERROR - Failed to execute job 64 for task PostgresTable (could not translate host name "host.local.internal" to address: Name or service not known
; 20389)
[2024-01-05T13:22:02.174+0000] {local_task_job_runner.py:234} INFO - Task exited with return code 1
[2024-01-05T13:22:02.227+0000] {taskinstance.py:3281} INFO - 0 downstream tasks scheduled from follow-on schedule check
