[2024-01-05T15:01:31.759+0000] {logging_mixin.py:188} INFO - Changing /opt/***/logs/dag_id=User_counter/run_id=scheduled__2024-01-05T15:00:00+00:00/task_id=PostgresTable permission to 509
[2024-01-05T15:01:31.760+0000] {logging_mixin.py:188} INFO - Failed to change /opt/***/logs/dag_id=User_counter/run_id=scheduled__2024-01-05T15:00:00+00:00/task_id=PostgresTable permission to 509: [Errno 1] Operation not permitted: '/opt/***/logs/dag_id=User_counter/run_id=scheduled__2024-01-05T15:00:00+00:00/task_id=PostgresTable'
[2024-01-05T15:01:31.793+0000] {logging_mixin.py:188} INFO - Changing /opt/***/logs/dag_id=User_counter/run_id=scheduled__2024-01-05T15:00:00+00:00/task_id=PostgresTable permission to 509
[2024-01-05T15:01:31.794+0000] {logging_mixin.py:188} INFO - Failed to change /opt/***/logs/dag_id=User_counter/run_id=scheduled__2024-01-05T15:00:00+00:00/task_id=PostgresTable permission to 509: [Errno 1] Operation not permitted: '/opt/***/logs/dag_id=User_counter/run_id=scheduled__2024-01-05T15:00:00+00:00/task_id=PostgresTable'
[2024-01-05T15:01:31.835+0000] {taskinstance.py:1957} INFO - Dependencies all met for dep_context=non-requeueable deps ti=<TaskInstance: User_counter.PostgresTable scheduled__2024-01-05T15:00:00+00:00 [queued]>
[2024-01-05T15:01:31.844+0000] {taskinstance.py:1957} INFO - Dependencies all met for dep_context=requeueable deps ti=<TaskInstance: User_counter.PostgresTable scheduled__2024-01-05T15:00:00+00:00 [queued]>
[2024-01-05T15:01:31.845+0000] {taskinstance.py:2171} INFO - Starting attempt 2 of 2
[2024-01-05T15:01:31.861+0000] {taskinstance.py:2192} INFO - Executing <Task(PostgresOperator): PostgresTable> on 2024-01-05 15:00:00+00:00
[2024-01-05T15:01:31.866+0000] {standard_task_runner.py:60} INFO - Started process 332 to run task
[2024-01-05T15:01:31.870+0000] {standard_task_runner.py:87} INFO - Running: ['***', 'tasks', 'run', 'User_counter', 'PostgresTable', 'scheduled__2024-01-05T15:00:00+00:00', '--job-id', '6', '--raw', '--subdir', 'DAGS_FOLDER/User_counter.py', '--cfg-path', '/tmp/tmpm0vcd5cx']
[2024-01-05T15:01:31.873+0000] {standard_task_runner.py:88} INFO - Job 6: Subtask PostgresTable
[2024-01-05T15:01:31.935+0000] {logging_mixin.py:188} INFO - Changing /opt/***/logs/dag_id=User_counter/run_id=scheduled__2024-01-05T15:00:00+00:00/task_id=PostgresTable permission to 509
[2024-01-05T15:01:31.935+0000] {logging_mixin.py:188} INFO - Failed to change /opt/***/logs/dag_id=User_counter/run_id=scheduled__2024-01-05T15:00:00+00:00/task_id=PostgresTable permission to 509: [Errno 1] Operation not permitted: '/opt/***/logs/dag_id=User_counter/run_id=scheduled__2024-01-05T15:00:00+00:00/task_id=PostgresTable'
[2024-01-05T15:01:31.937+0000] {task_command.py:423} INFO - Running <TaskInstance: User_counter.PostgresTable scheduled__2024-01-05T15:00:00+00:00 [running]> on host 62c5474f7307
[2024-01-05T15:01:32.022+0000] {taskinstance.py:2481} INFO - Exporting env vars: AIRFLOW_CTX_DAG_OWNER='Airflow' AIRFLOW_CTX_DAG_ID='User_counter' AIRFLOW_CTX_TASK_ID='PostgresTable' AIRFLOW_CTX_EXECUTION_DATE='2024-01-05T15:00:00+00:00' AIRFLOW_CTX_TRY_NUMBER='2' AIRFLOW_CTX_DAG_RUN_ID='scheduled__2024-01-05T15:00:00+00:00'
[2024-01-05T15:01:32.023+0000] {sql.py:276} INFO - Executing: 
            CREATE TABLE IF NOT EXISTS pet (
            pet_id SERIAL PRIMARY KEY,
            name VARCHAR NOT NULL,
            pet_type VARCHAR NOT NULL,
            birth_date DATE NOT NULL,
            OWNER VARCHAR NOT NULL);
          
[2024-01-05T15:01:32.042+0000] {taskinstance.py:2699} ERROR - Task failed with exception
Traceback (most recent call last):
  File "/home/airflow/.local/lib/python3.8/site-packages/airflow/models/taskinstance.py", line 433, in _execute_task
    result = execute_callable(context=context, **execute_callable_kwargs)
  File "/home/airflow/.local/lib/python3.8/site-packages/airflow/providers/common/sql/operators/sql.py", line 277, in execute
    hook = self.get_db_hook()
  File "/home/airflow/.local/lib/python3.8/site-packages/airflow/providers/common/sql/operators/sql.py", line 188, in get_db_hook
    return self._hook
  File "/usr/local/lib/python3.8/functools.py", line 967, in __get__
    val = self.func(instance)
  File "/home/airflow/.local/lib/python3.8/site-packages/airflow/providers/common/sql/operators/sql.py", line 150, in _hook
    conn = BaseHook.get_connection(conn_id)
  File "/home/airflow/.local/lib/python3.8/site-packages/airflow/hooks/base.py", line 82, in get_connection
    conn = Connection.get_connection_from_secrets(conn_id)
  File "/home/airflow/.local/lib/python3.8/site-packages/airflow/models/connection.py", line 479, in get_connection_from_secrets
    raise AirflowNotFoundException(f"The conn_id `{conn_id}` isn't defined")
airflow.exceptions.AirflowNotFoundException: The conn_id `postgres_default` isn't defined
[2024-01-05T15:01:32.046+0000] {taskinstance.py:1138} INFO - Marking task as FAILED. dag_id=User_counter, task_id=PostgresTable, execution_date=20240105T150000, start_date=20240105T150131, end_date=20240105T150132
[2024-01-05T15:01:32.061+0000] {standard_task_runner.py:107} ERROR - Failed to execute job 6 for task PostgresTable (The conn_id `postgres_default` isn't defined; 332)
[2024-01-05T15:01:32.082+0000] {local_task_job_runner.py:234} INFO - Task exited with return code 1
[2024-01-05T15:01:32.111+0000] {taskinstance.py:3281} INFO - 0 downstream tasks scheduled from follow-on schedule check
