[2024-01-05T13:21:55.169+0000] {logging_mixin.py:188} INFO - Changing /opt/***/logs/dag_id=User_counter/run_id=scheduled__2024-01-05T13:16:00+00:00/task_id=PostgresTable permission to 509
[2024-01-05T13:21:55.169+0000] {logging_mixin.py:188} INFO - Failed to change /opt/***/logs/dag_id=User_counter/run_id=scheduled__2024-01-05T13:16:00+00:00/task_id=PostgresTable permission to 509: [Errno 1] Operation not permitted: '/opt/***/logs/dag_id=User_counter/run_id=scheduled__2024-01-05T13:16:00+00:00/task_id=PostgresTable'
[2024-01-05T13:21:55.214+0000] {logging_mixin.py:188} INFO - Changing /opt/***/logs/dag_id=User_counter/run_id=scheduled__2024-01-05T13:16:00+00:00/task_id=PostgresTable permission to 509
[2024-01-05T13:21:55.215+0000] {logging_mixin.py:188} INFO - Failed to change /opt/***/logs/dag_id=User_counter/run_id=scheduled__2024-01-05T13:16:00+00:00/task_id=PostgresTable permission to 509: [Errno 1] Operation not permitted: '/opt/***/logs/dag_id=User_counter/run_id=scheduled__2024-01-05T13:16:00+00:00/task_id=PostgresTable'
[2024-01-05T13:21:55.254+0000] {taskinstance.py:1957} INFO - Dependencies all met for dep_context=non-requeueable deps ti=<TaskInstance: User_counter.PostgresTable scheduled__2024-01-05T13:16:00+00:00 [queued]>
[2024-01-05T13:21:55.264+0000] {taskinstance.py:1957} INFO - Dependencies all met for dep_context=requeueable deps ti=<TaskInstance: User_counter.PostgresTable scheduled__2024-01-05T13:16:00+00:00 [queued]>
[2024-01-05T13:21:55.264+0000] {taskinstance.py:2171} INFO - Starting attempt 2 of 2
[2024-01-05T13:21:55.283+0000] {taskinstance.py:2192} INFO - Executing <Task(PostgresOperator): PostgresTable> on 2024-01-05 13:16:00+00:00
[2024-01-05T13:21:55.289+0000] {standard_task_runner.py:60} INFO - Started process 20283 to run task
[2024-01-05T13:21:55.294+0000] {standard_task_runner.py:87} INFO - Running: ['***', 'tasks', 'run', 'User_counter', 'PostgresTable', 'scheduled__2024-01-05T13:16:00+00:00', '--job-id', '63', '--raw', '--subdir', 'DAGS_FOLDER/User_counter.py', '--cfg-path', '/tmp/tmpm7smosly']
[2024-01-05T13:21:55.298+0000] {standard_task_runner.py:88} INFO - Job 63: Subtask PostgresTable
[2024-01-05T13:21:55.363+0000] {logging_mixin.py:188} INFO - Changing /opt/***/logs/dag_id=User_counter/run_id=scheduled__2024-01-05T13:16:00+00:00/task_id=PostgresTable permission to 509
[2024-01-05T13:21:55.364+0000] {logging_mixin.py:188} INFO - Failed to change /opt/***/logs/dag_id=User_counter/run_id=scheduled__2024-01-05T13:16:00+00:00/task_id=PostgresTable permission to 509: [Errno 1] Operation not permitted: '/opt/***/logs/dag_id=User_counter/run_id=scheduled__2024-01-05T13:16:00+00:00/task_id=PostgresTable'
[2024-01-05T13:21:55.366+0000] {task_command.py:423} INFO - Running <TaskInstance: User_counter.PostgresTable scheduled__2024-01-05T13:16:00+00:00 [running]> on host b8b6020a6ce0
[2024-01-05T13:21:55.467+0000] {taskinstance.py:2481} INFO - Exporting env vars: AIRFLOW_CTX_DAG_OWNER='Airflow' AIRFLOW_CTX_DAG_ID='User_counter' AIRFLOW_CTX_TASK_ID='PostgresTable' AIRFLOW_CTX_EXECUTION_DATE='2024-01-05T13:16:00+00:00' AIRFLOW_CTX_TRY_NUMBER='2' AIRFLOW_CTX_DAG_RUN_ID='scheduled__2024-01-05T13:16:00+00:00'
[2024-01-05T13:21:55.471+0000] {sql.py:276} INFO - Executing: 
            CREATE TABLE IF NOT EXISTS pet (
            pet_id SERIAL PRIMARY KEY,
            name VARCHAR NOT NULL,
            pet_type VARCHAR NOT NULL,
            birth_date DATE NOT NULL,
            OWNER VARCHAR NOT NULL);
          
[2024-01-05T13:21:55.480+0000] {base.py:83} INFO - Using connection ID 'Postgres-connection' for task execution.
[2024-01-05T13:21:55.490+0000] {base.py:83} INFO - Using connection ID 'Postgres-connection' for task execution.
[2024-01-05T13:21:55.522+0000] {taskinstance.py:2699} ERROR - Task failed with exception
Traceback (most recent call last):
  File "/home/airflow/.local/lib/python3.8/site-packages/airflow/models/taskinstance.py", line 433, in _execute_task
    result = execute_callable(context=context, **execute_callable_kwargs)
  File "/home/airflow/.local/lib/python3.8/site-packages/airflow/providers/common/sql/operators/sql.py", line 282, in execute
    output = hook.run(
  File "/home/airflow/.local/lib/python3.8/site-packages/airflow/providers/common/sql/hooks/sql.py", line 385, in run
    with closing(self.get_conn()) as conn:
  File "/home/airflow/.local/lib/python3.8/site-packages/airflow/providers/postgres/hooks/postgres.py", line 158, in get_conn
    self.conn = psycopg2.connect(**conn_args)
  File "/home/airflow/.local/lib/python3.8/site-packages/psycopg2/__init__.py", line 122, in connect
    conn = _connect(dsn, connection_factory=connection_factory, **kwasync)
psycopg2.OperationalError: could not translate host name "host.local.internal" to address: Name or service not known

[2024-01-05T13:21:55.532+0000] {taskinstance.py:1138} INFO - Marking task as FAILED. dag_id=User_counter, task_id=PostgresTable, execution_date=20240105T131600, start_date=20240105T132155, end_date=20240105T132155
[2024-01-05T13:21:55.544+0000] {standard_task_runner.py:107} ERROR - Failed to execute job 63 for task PostgresTable (could not translate host name "host.local.internal" to address: Name or service not known
; 20283)
[2024-01-05T13:21:55.587+0000] {local_task_job_runner.py:234} INFO - Task exited with return code 1
[2024-01-05T13:21:55.613+0000] {taskinstance.py:3281} INFO - 0 downstream tasks scheduled from follow-on schedule check
