[2024-01-05T12:52:01.671+0000] {logging_mixin.py:188} INFO - Changing /opt/***/logs/dag_id=User_counter/run_id=scheduled__2024-01-05T12:51:00+00:00/task_id=PostgresTable permission to 509
[2024-01-05T12:52:01.672+0000] {logging_mixin.py:188} INFO - Failed to change /opt/***/logs/dag_id=User_counter/run_id=scheduled__2024-01-05T12:51:00+00:00/task_id=PostgresTable permission to 509: [Errno 1] Operation not permitted: '/opt/***/logs/dag_id=User_counter/run_id=scheduled__2024-01-05T12:51:00+00:00/task_id=PostgresTable'
[2024-01-05T12:52:01.704+0000] {logging_mixin.py:188} INFO - Changing /opt/***/logs/dag_id=User_counter/run_id=scheduled__2024-01-05T12:51:00+00:00/task_id=PostgresTable permission to 509
[2024-01-05T12:52:01.704+0000] {logging_mixin.py:188} INFO - Failed to change /opt/***/logs/dag_id=User_counter/run_id=scheduled__2024-01-05T12:51:00+00:00/task_id=PostgresTable permission to 509: [Errno 1] Operation not permitted: '/opt/***/logs/dag_id=User_counter/run_id=scheduled__2024-01-05T12:51:00+00:00/task_id=PostgresTable'
[2024-01-05T12:52:01.745+0000] {taskinstance.py:1957} INFO - Dependencies all met for dep_context=non-requeueable deps ti=<TaskInstance: User_counter.PostgresTable scheduled__2024-01-05T12:51:00+00:00 [queued]>
[2024-01-05T12:52:01.761+0000] {taskinstance.py:1957} INFO - Dependencies all met for dep_context=requeueable deps ti=<TaskInstance: User_counter.PostgresTable scheduled__2024-01-05T12:51:00+00:00 [queued]>
[2024-01-05T12:52:01.762+0000] {taskinstance.py:2171} INFO - Starting attempt 1 of 2
[2024-01-05T12:52:01.776+0000] {taskinstance.py:2192} INFO - Executing <Task(PostgresOperator): PostgresTable> on 2024-01-05 12:51:00+00:00
[2024-01-05T12:52:01.782+0000] {standard_task_runner.py:60} INFO - Started process 4799 to run task
[2024-01-05T12:52:01.787+0000] {standard_task_runner.py:87} INFO - Running: ['***', 'tasks', 'run', 'User_counter', 'PostgresTable', 'scheduled__2024-01-05T12:51:00+00:00', '--job-id', '19', '--raw', '--subdir', 'DAGS_FOLDER/User_counter.py', '--cfg-path', '/tmp/tmplydb7h2q']
[2024-01-05T12:52:01.791+0000] {standard_task_runner.py:88} INFO - Job 19: Subtask PostgresTable
[2024-01-05T12:52:01.850+0000] {logging_mixin.py:188} INFO - Changing /opt/***/logs/dag_id=User_counter/run_id=scheduled__2024-01-05T12:51:00+00:00/task_id=PostgresTable permission to 509
[2024-01-05T12:52:01.851+0000] {logging_mixin.py:188} INFO - Failed to change /opt/***/logs/dag_id=User_counter/run_id=scheduled__2024-01-05T12:51:00+00:00/task_id=PostgresTable permission to 509: [Errno 1] Operation not permitted: '/opt/***/logs/dag_id=User_counter/run_id=scheduled__2024-01-05T12:51:00+00:00/task_id=PostgresTable'
[2024-01-05T12:52:01.853+0000] {task_command.py:423} INFO - Running <TaskInstance: User_counter.PostgresTable scheduled__2024-01-05T12:51:00+00:00 [running]> on host b8b6020a6ce0
[2024-01-05T12:52:01.951+0000] {taskinstance.py:2481} INFO - Exporting env vars: AIRFLOW_CTX_DAG_OWNER='Airflow' AIRFLOW_CTX_DAG_ID='User_counter' AIRFLOW_CTX_TASK_ID='PostgresTable' AIRFLOW_CTX_EXECUTION_DATE='2024-01-05T12:51:00+00:00' AIRFLOW_CTX_TRY_NUMBER='1' AIRFLOW_CTX_DAG_RUN_ID='scheduled__2024-01-05T12:51:00+00:00'
[2024-01-05T12:52:01.954+0000] {sql.py:276} INFO - Executing: 
            CREATE TABLE IF NOT EXISTS pet (
            pet_id SERIAL PRIMARY KEY,
            name VARCHAR NOT NULL,
            pet_type VARCHAR NOT NULL,
            birth_date DATE NOT NULL,
            OWNER VARCHAR NOT NULL);
          
[2024-01-05T12:52:01.968+0000] {base.py:83} INFO - Using connection ID 'Postgres-connection' for task execution.
[2024-01-05T12:52:01.983+0000] {base.py:83} INFO - Using connection ID 'Postgres-connection' for task execution.
[2024-01-05T12:52:01.989+0000] {taskinstance.py:2699} ERROR - Task failed with exception
Traceback (most recent call last):
  File "/home/airflow/.local/lib/python3.8/site-packages/airflow/models/taskinstance.py", line 433, in _execute_task
    result = execute_callable(context=context, **execute_callable_kwargs)
  File "/home/airflow/.local/lib/python3.8/site-packages/airflow/providers/common/sql/operators/sql.py", line 282, in execute
    output = hook.run(
  File "/home/airflow/.local/lib/python3.8/site-packages/airflow/providers/common/sql/hooks/sql.py", line 385, in run
    with closing(self.get_conn()) as conn:
  File "/home/airflow/.local/lib/python3.8/site-packages/airflow/providers/postgres/hooks/postgres.py", line 158, in get_conn
    self.conn = psycopg2.connect(**conn_args)
  File "/home/airflow/.local/lib/python3.8/site-packages/psycopg2/__init__.py", line 122, in connect
    conn = _connect(dsn, connection_factory=connection_factory, **kwasync)
psycopg2.OperationalError: connection to server at "postgres" (172.24.0.2), port 5432 failed: FATAL:  password authentication failed for user "postgres"

[2024-01-05T12:52:02.002+0000] {taskinstance.py:1138} INFO - Marking task as UP_FOR_RETRY. dag_id=User_counter, task_id=PostgresTable, execution_date=20240105T125100, start_date=20240105T125201, end_date=20240105T125202
[2024-01-05T12:52:02.030+0000] {standard_task_runner.py:107} ERROR - Failed to execute job 19 for task PostgresTable (connection to server at "postgres" (172.24.0.2), port 5432 failed: FATAL:  password authentication failed for user "postgres"
; 4799)
[2024-01-05T12:52:02.043+0000] {local_task_job_runner.py:234} INFO - Task exited with return code 1
[2024-01-05T12:52:02.071+0000] {taskinstance.py:3281} INFO - 0 downstream tasks scheduled from follow-on schedule check
