[2024-01-05T14:29:03.380+0000] {logging_mixin.py:188} INFO - Changing /opt/***/logs/dag_id=User_counter/run_id=scheduled__2024-01-05T14:28:00+00:00/task_id=PostgresTable permission to 509
[2024-01-05T14:29:03.381+0000] {logging_mixin.py:188} INFO - Failed to change /opt/***/logs/dag_id=User_counter/run_id=scheduled__2024-01-05T14:28:00+00:00/task_id=PostgresTable permission to 509: [Errno 1] Operation not permitted: '/opt/***/logs/dag_id=User_counter/run_id=scheduled__2024-01-05T14:28:00+00:00/task_id=PostgresTable'
[2024-01-05T14:29:03.525+0000] {logging_mixin.py:188} INFO - Changing /opt/***/logs/dag_id=User_counter/run_id=scheduled__2024-01-05T14:28:00+00:00/task_id=PostgresTable permission to 509
[2024-01-05T14:29:03.529+0000] {logging_mixin.py:188} INFO - Failed to change /opt/***/logs/dag_id=User_counter/run_id=scheduled__2024-01-05T14:28:00+00:00/task_id=PostgresTable permission to 509: [Errno 1] Operation not permitted: '/opt/***/logs/dag_id=User_counter/run_id=scheduled__2024-01-05T14:28:00+00:00/task_id=PostgresTable'
[2024-01-05T14:29:03.641+0000] {taskinstance.py:1957} INFO - Dependencies all met for dep_context=non-requeueable deps ti=<TaskInstance: User_counter.PostgresTable scheduled__2024-01-05T14:28:00+00:00 [queued]>
[2024-01-05T14:29:03.656+0000] {taskinstance.py:1957} INFO - Dependencies all met for dep_context=requeueable deps ti=<TaskInstance: User_counter.PostgresTable scheduled__2024-01-05T14:28:00+00:00 [queued]>
[2024-01-05T14:29:03.657+0000] {taskinstance.py:2171} INFO - Starting attempt 1 of 2
[2024-01-05T14:29:03.708+0000] {taskinstance.py:2192} INFO - Executing <Task(PostgresOperator): PostgresTable> on 2024-01-05 14:28:00+00:00
[2024-01-05T14:29:03.716+0000] {standard_task_runner.py:60} INFO - Started process 2615 to run task
[2024-01-05T14:29:03.729+0000] {standard_task_runner.py:87} INFO - Running: ['***', 'tasks', 'run', 'User_counter', 'PostgresTable', 'scheduled__2024-01-05T14:28:00+00:00', '--job-id', '9', '--raw', '--subdir', 'DAGS_FOLDER/User_counter.py', '--cfg-path', '/tmp/tmpqikbul28']
[2024-01-05T14:29:03.733+0000] {standard_task_runner.py:88} INFO - Job 9: Subtask PostgresTable
[2024-01-05T14:29:03.822+0000] {logging_mixin.py:188} INFO - Changing /opt/***/logs/dag_id=User_counter/run_id=scheduled__2024-01-05T14:28:00+00:00/task_id=PostgresTable permission to 509
[2024-01-05T14:29:03.823+0000] {logging_mixin.py:188} INFO - Failed to change /opt/***/logs/dag_id=User_counter/run_id=scheduled__2024-01-05T14:28:00+00:00/task_id=PostgresTable permission to 509: [Errno 1] Operation not permitted: '/opt/***/logs/dag_id=User_counter/run_id=scheduled__2024-01-05T14:28:00+00:00/task_id=PostgresTable'
[2024-01-05T14:29:03.827+0000] {task_command.py:423} INFO - Running <TaskInstance: User_counter.PostgresTable scheduled__2024-01-05T14:28:00+00:00 [running]> on host 6904393207eb
[2024-01-05T14:29:03.943+0000] {taskinstance.py:2481} INFO - Exporting env vars: AIRFLOW_CTX_DAG_OWNER='Airflow' AIRFLOW_CTX_DAG_ID='User_counter' AIRFLOW_CTX_TASK_ID='PostgresTable' AIRFLOW_CTX_EXECUTION_DATE='2024-01-05T14:28:00+00:00' AIRFLOW_CTX_TRY_NUMBER='1' AIRFLOW_CTX_DAG_RUN_ID='scheduled__2024-01-05T14:28:00+00:00'
[2024-01-05T14:29:03.946+0000] {sql.py:276} INFO - Executing: 
            CREATE TABLE IF NOT EXISTS users_count (
            count INTEGER NOT NULL,
            date DATETIME  NOT NULL DEFAULT(GETDATE()));
          
[2024-01-05T14:29:03.973+0000] {taskinstance.py:2699} ERROR - Task failed with exception
Traceback (most recent call last):
  File "/home/airflow/.local/lib/python3.8/site-packages/airflow/models/taskinstance.py", line 433, in _execute_task
    result = execute_callable(context=context, **execute_callable_kwargs)
  File "/home/airflow/.local/lib/python3.8/site-packages/airflow/providers/common/sql/operators/sql.py", line 277, in execute
    hook = self.get_db_hook()
  File "/home/airflow/.local/lib/python3.8/site-packages/airflow/providers/common/sql/operators/sql.py", line 188, in get_db_hook
    return self._hook
  File "/usr/local/lib/python3.8/functools.py", line 967, in __get__
    val = self.func(instance)
  File "/home/airflow/.local/lib/python3.8/site-packages/airflow/providers/common/sql/operators/sql.py", line 150, in _hook
    conn = BaseHook.get_connection(conn_id)
  File "/home/airflow/.local/lib/python3.8/site-packages/airflow/hooks/base.py", line 82, in get_connection
    conn = Connection.get_connection_from_secrets(conn_id)
  File "/home/airflow/.local/lib/python3.8/site-packages/airflow/models/connection.py", line 479, in get_connection_from_secrets
    raise AirflowNotFoundException(f"The conn_id `{conn_id}` isn't defined")
airflow.exceptions.AirflowNotFoundException: The conn_id `postgres_default` isn't defined
[2024-01-05T14:29:03.978+0000] {taskinstance.py:1138} INFO - Marking task as UP_FOR_RETRY. dag_id=User_counter, task_id=PostgresTable, execution_date=20240105T142800, start_date=20240105T142903, end_date=20240105T142903
[2024-01-05T14:29:03.996+0000] {standard_task_runner.py:107} ERROR - Failed to execute job 9 for task PostgresTable (The conn_id `postgres_default` isn't defined; 2615)
[2024-01-05T14:29:04.020+0000] {local_task_job_runner.py:234} INFO - Task exited with return code 1
[2024-01-05T14:29:04.051+0000] {taskinstance.py:3281} INFO - 0 downstream tasks scheduled from follow-on schedule check
