[2024-01-05T14:29:35.213+0000] {logging_mixin.py:188} INFO - Changing /opt/***/logs/dag_id=User_counter/run_id=scheduled__2024-01-05T14:28:00+00:00/task_id=PostgresTable permission to 509
[2024-01-05T14:29:35.214+0000] {logging_mixin.py:188} INFO - Failed to change /opt/***/logs/dag_id=User_counter/run_id=scheduled__2024-01-05T14:28:00+00:00/task_id=PostgresTable permission to 509: [Errno 1] Operation not permitted: '/opt/***/logs/dag_id=User_counter/run_id=scheduled__2024-01-05T14:28:00+00:00/task_id=PostgresTable'
[2024-01-05T14:29:35.246+0000] {logging_mixin.py:188} INFO - Changing /opt/***/logs/dag_id=User_counter/run_id=scheduled__2024-01-05T14:28:00+00:00/task_id=PostgresTable permission to 509
[2024-01-05T14:29:35.246+0000] {logging_mixin.py:188} INFO - Failed to change /opt/***/logs/dag_id=User_counter/run_id=scheduled__2024-01-05T14:28:00+00:00/task_id=PostgresTable permission to 509: [Errno 1] Operation not permitted: '/opt/***/logs/dag_id=User_counter/run_id=scheduled__2024-01-05T14:28:00+00:00/task_id=PostgresTable'
[2024-01-05T14:29:35.294+0000] {taskinstance.py:1957} INFO - Dependencies all met for dep_context=non-requeueable deps ti=<TaskInstance: User_counter.PostgresTable scheduled__2024-01-05T14:28:00+00:00 [queued]>
[2024-01-05T14:29:35.325+0000] {taskinstance.py:1957} INFO - Dependencies all met for dep_context=requeueable deps ti=<TaskInstance: User_counter.PostgresTable scheduled__2024-01-05T14:28:00+00:00 [queued]>
[2024-01-05T14:29:35.326+0000] {taskinstance.py:2171} INFO - Starting attempt 2 of 2
[2024-01-05T14:29:35.348+0000] {taskinstance.py:2192} INFO - Executing <Task(PostgresOperator): PostgresTable> on 2024-01-05 14:28:00+00:00
[2024-01-05T14:29:35.359+0000] {standard_task_runner.py:60} INFO - Started process 2896 to run task
[2024-01-05T14:29:35.370+0000] {standard_task_runner.py:87} INFO - Running: ['***', 'tasks', 'run', 'User_counter', 'PostgresTable', 'scheduled__2024-01-05T14:28:00+00:00', '--job-id', '10', '--raw', '--subdir', 'DAGS_FOLDER/User_counter.py', '--cfg-path', '/tmp/tmpyw973f0c']
[2024-01-05T14:29:35.377+0000] {standard_task_runner.py:88} INFO - Job 10: Subtask PostgresTable
[2024-01-05T14:29:35.457+0000] {logging_mixin.py:188} INFO - Changing /opt/***/logs/dag_id=User_counter/run_id=scheduled__2024-01-05T14:28:00+00:00/task_id=PostgresTable permission to 509
[2024-01-05T14:29:35.458+0000] {logging_mixin.py:188} INFO - Failed to change /opt/***/logs/dag_id=User_counter/run_id=scheduled__2024-01-05T14:28:00+00:00/task_id=PostgresTable permission to 509: [Errno 1] Operation not permitted: '/opt/***/logs/dag_id=User_counter/run_id=scheduled__2024-01-05T14:28:00+00:00/task_id=PostgresTable'
[2024-01-05T14:29:35.459+0000] {task_command.py:423} INFO - Running <TaskInstance: User_counter.PostgresTable scheduled__2024-01-05T14:28:00+00:00 [running]> on host 6904393207eb
[2024-01-05T14:29:35.539+0000] {taskinstance.py:2481} INFO - Exporting env vars: AIRFLOW_CTX_DAG_OWNER='Airflow' AIRFLOW_CTX_DAG_ID='User_counter' AIRFLOW_CTX_TASK_ID='PostgresTable' AIRFLOW_CTX_EXECUTION_DATE='2024-01-05T14:28:00+00:00' AIRFLOW_CTX_TRY_NUMBER='2' AIRFLOW_CTX_DAG_RUN_ID='scheduled__2024-01-05T14:28:00+00:00'
[2024-01-05T14:29:35.542+0000] {sql.py:276} INFO - Executing: 
            CREATE TABLE IF NOT EXISTS users_count (
            count INTEGER NOT NULL,
            date DATETIME  NOT NULL DEFAULT(GETDATE()));
          
[2024-01-05T14:29:35.552+0000] {base.py:83} INFO - Using connection ID 'postgres_default' for task execution.
[2024-01-05T14:29:35.568+0000] {base.py:83} INFO - Using connection ID 'postgres_default' for task execution.
[2024-01-05T14:29:35.570+0000] {taskinstance.py:2699} ERROR - Task failed with exception
Traceback (most recent call last):
  File "/home/airflow/.local/lib/python3.8/site-packages/airflow/models/taskinstance.py", line 433, in _execute_task
    result = execute_callable(context=context, **execute_callable_kwargs)
  File "/home/airflow/.local/lib/python3.8/site-packages/airflow/providers/common/sql/operators/sql.py", line 282, in execute
    output = hook.run(
  File "/home/airflow/.local/lib/python3.8/site-packages/airflow/providers/common/sql/hooks/sql.py", line 385, in run
    with closing(self.get_conn()) as conn:
  File "/home/airflow/.local/lib/python3.8/site-packages/airflow/providers/postgres/hooks/postgres.py", line 158, in get_conn
    self.conn = psycopg2.connect(**conn_args)
  File "/home/airflow/.local/lib/python3.8/site-packages/psycopg2/__init__.py", line 122, in connect
    conn = _connect(dsn, connection_factory=connection_factory, **kwasync)
psycopg2.OperationalError: connection to server on socket "/var/run/postgresql/.s.PGSQL.5432" failed: No such file or directory
	Is the server running locally and accepting connections on that socket?

[2024-01-05T14:29:35.581+0000] {taskinstance.py:1138} INFO - Marking task as FAILED. dag_id=User_counter, task_id=PostgresTable, execution_date=20240105T142800, start_date=20240105T142935, end_date=20240105T142935
[2024-01-05T14:29:35.602+0000] {standard_task_runner.py:107} ERROR - Failed to execute job 10 for task PostgresTable (connection to server on socket "/var/run/postgresql/.s.PGSQL.5432" failed: No such file or directory
	Is the server running locally and accepting connections on that socket?
; 2896)
[2024-01-05T14:29:35.619+0000] {local_task_job_runner.py:234} INFO - Task exited with return code 1
[2024-01-05T14:29:35.665+0000] {taskinstance.py:3281} INFO - 0 downstream tasks scheduled from follow-on schedule check
